<mujoco model="T170-V2.1">
  <compiler angle="radian" meshdir="../meshes/" eulerseq="zyx"/>
    <option timestep='0.001' iterations='50' solver='PGS' gravity='0 0 -9.81'>
    <flag sensornoise="enable" frictionloss="enable"/>
    </option>
    <size njmax="500" nconmax="100" />

    <visual>
        <quality shadowsize='4096'/>
        <map znear='0.05'/>
    </visual>

  
      <default>
        <joint limited='true'/>
        <motor ctrllimited='true'/>
        <geom  condim='4' contype="1" conaffinity="15" solref='0.001 2' friction='0.9 0.2 0.2'/>
        <equality solref='0.001 2'/>
        <default class='visualgeom'>
            <geom material='visualgeom' condim='1' contype='0' conaffinity='0'/>
        </default>
        <default class='visualgeom2'>
            <geom material='visualgeom2' condim='1' contype='0' conaffinity='0'/>
        </default>
        <default class='obstacle'>
            <geom material='obstacle' condim='3' contype='1' conaffinity='15'/>
        </default>
      

        <default class='neck_joint_param'>
            <joint  damping="0.01" frictionloss="0.01" armature="0.01"/>
        </default>

        <default class='waist_joint_param'>
            <joint  damping="2" frictionloss="2" armature="0.01"/>
        </default>

        <default class='leg_joint_param'>
            <joint  damping="0.01" frictionloss="0.01" armature="0.01"/>
        </default>

        <default class='arm_joint_param'>
            <joint  damping="1" frictionloss="1" armature="0.01"/>
        </default>  

        <default class='finger_joint_param'>
            <joint  damping="0.00" frictionloss="0.00" armature="0.01"/>
        </default> 
    </default>

  <asset>
    <mesh name="BASE_S" file="BASE_S.STL"/>
    <mesh name="L_HIP_P_S" file="L_HIP_P_S.STL"/>
    <mesh name="L_HIP_R_S" file="L_HIP_R_S.STL"/>
    <mesh name="L_HIP_Y_S" file="L_HIP_Y_S.STL"/>
    <mesh name="L_KNEE_P_S" file="L_KNEE_P_S.STL"/>
    <mesh name="L_ANKLE_P_S" file="L_ANKLE_P_S.STL"/>
    <mesh name="L_ANKLE_R_S" file="L_ANKLE_R_S.STL"/>
    <mesh name="R_HIP_P_S" file="R_HIP_P_S.STL"/>
    <mesh name="R_HIP_R_S" file="R_HIP_R_S.STL"/>
    <mesh name="R_HIP_Y_S" file="R_HIP_Y_S.STL"/>
    <mesh name="R_KNEE_P_S" file="R_KNEE_P_S.STL"/>
    <mesh name="R_ANKLE_P_S" file="R_ANKLE_P_S.STL"/>
    <mesh name="R_ANKLE_R_S" file="R_ANKLE_R_S.STL"/>
    <mesh name="WAIST_Y_S" file="WAIST_Y_S.STL"/>
    <mesh name="WAIST_R_S" file="WAIST_R_S.STL"/>
    <mesh name="WAIST_P_S" file="WAIST_P_S.STL"/>
    <mesh name="L_SHOULDER_P_S" file="L_SHOULDER_P_S.STL"/>
    <mesh name="L_SHOULDER_R_S" file="L_SHOULDER_R_S.STL"/>
    <mesh name="L_SHOULDER_Y_S" file="L_SHOULDER_Y_S.STL"/>
    <mesh name="L_ELBOW_Y_S" file="L_ELBOW_Y_S.STL"/>
    <mesh name="L_WRIST_P_S" file="L_WRIST_P_S.STL"/>
    <mesh name="L_WRIST_Y_S" file="L_WRIST_Y_S.STL"/>
    <mesh name="L_WRIST_R_S" file="L_WRIST_R_S.STL"/>
    <mesh name="R_SHOULDER_P_S" file="R_SHOULDER_P_S.STL"/>
    <mesh name="R_SHOULDER_R_S" file="R_SHOULDER_R_S.STL"/>
    <mesh name="R_SHOULDER_Y_S" file="R_SHOULDER_Y_S.STL"/>
    <mesh name="R_ELBOW_Y_S" file="R_ELBOW_Y_S.STL"/>
    <mesh name="R_WRIST_P_S" file="R_WRIST_P_S.STL"/>
    <mesh name="R_WRIST_Y_S" file="R_WRIST_Y_S.STL"/>
    <mesh name="R_WRIST_R_S" file="R_WRIST_R_S.STL"/>
    <mesh name="NECK_Y_S" file="NECK_Y_S.STL"/>
  </asset>

  <worldbody>
    <light directional="true" diffuse=".4 .4 .4" specular="0.1 0.1 0.1" pos="0 0 5.0" dir="0 0 -1" castshadow="false"/>
    <light directional="true" diffuse=".6 .6 .6" specular="0.2 0.2 0.2" pos="0 0 4" dir="0 0 -1"/>
    <geom name="ground" type="plane" size="0 0 1" pos="0.001 0 0" quat="1 0 0 0" material="matplane" condim="1" conaffinity='15'/>

    <body name="BASE_S" pos="0.0 0.0 0.88">

    <!-- <body name="base_link" pos="0.0 0.0 0.92"> -->
      <geom type="mesh" mesh="BASE_S" group="1" class="visualgeom"/>

      <inertial pos="-0.0033599 -0.00084664 0.1336" mass="9.9576" diaginertia="0.089966 0.060002 0.056135" />
      <joint type='slide' axis='1 0 0' limited='false' />
      <joint type='slide' axis='0 1 0' limited='false' />
      <joint type='slide' axis='0 0 1' limited='false' />
      <joint type='ball' limited='false' />
      <site name='imu' size='0.01' pos='0.0 0 0.0'/>

    <geom type="mesh" contype="0" conaffinity="0" group="1" density="0" rgba="1 1 1 1" mesh="BASE_S"/>
    <!-- <geom size="0.125 0.25 0.2" pos="-0.01 0 0.2" type="box" rgba="1 1 1 1"/> -->
    <geom type="mesh" contype="0" conaffinity="0" group="1" density="0" rgba="0.898039 0.917647 0.929412 1" mesh="WAIST_Y_S"/>
    <geom pos="-0.0495 0 0.127" quat="1 0 0 0" type="mesh" contype="0" conaffinity="0" group="1" density="0" rgba="0.898039 0.917647 0.929412 1" mesh="WAIST_R_S"/>
    <geom pos="0 0.0465 0.127" type="mesh" contype="0" conaffinity="0" group="1" density="0" rgba="0.898039 0.917647 0.929412 1" mesh="WAIST_P_S"/>
    <geom pos="0.0005 0.124 0.463" quat="1 0 0 0" type="mesh" contype="0" conaffinity="0" group="1" density="0" rgba="0.898039 0.917647 0.929412 1" mesh="L_SHOULDER_P_S"/>
    <geom pos="0.0545 0.19 0.463" quat="0.764842 -0.644218 0 0" type="mesh" contype="0" conaffinity="0" group="1" density="0" rgba="0.898039 0.917647 0.929412 1" mesh="L_SHOULDER_R_S"/>
    <geom pos="0.0005 0.21371 0.32553" quat="0.764842 -0.644218 0 0" type="mesh" contype="0" conaffinity="0" group="1" density="0" rgba="0.898039 0.917647 0.929412 1" mesh="L_SHOULDER_Y_S"/>
    <geom pos="0.0005 0.291248 0.176033" quat="0.764842 -0.644218 0 0" type="mesh" contype="0" conaffinity="0" group="1" density="0" rgba="0.792157 0.819608 0.933333 1" mesh="L_ELBOW_Y_S"/>
    <geom pos="0.0005 0.262763 0.041129" quat="0.764842 -0.644218 0 0" type="mesh" contype="0" conaffinity="0" group="1" density="0" rgba="0.792157 0.819608 0.933333 1" mesh="L_WRIST_P_S"/>
    <geom pos="0.000590984 0.329235 -0.0942223" quat="0.764842 -0.644218 0 0" type="mesh" contype="0" conaffinity="0" group="1" density="0" rgba="0.792157 0.819608 0.933333 1" mesh="L_WRIST_Y_S"/>
    <geom pos="0.0315 0.288377 -0.101496" quat="0.764842 -0.644218 0 0" type="mesh" contype="0" conaffinity="0" group="1" density="0" rgba="0.792157 0.819608 0.933333 1" mesh="L_WRIST_R_S"/>
    <geom pos="0.0005 -0.124 0.463" quat="1 0 0 0" type="mesh" contype="0" conaffinity="0" group="1" density="0" rgba="0.898039 0.917647 0.929412 1" mesh="R_SHOULDER_P_S"/>
    <geom pos="0.0545 -0.19 0.463" quat="0.764842 0.644218 0 0" type="mesh" contype="0" conaffinity="0" group="1" density="0" rgba="0.898039 0.917647 0.929412 1" mesh="R_SHOULDER_R_S"/>
    <geom pos="0.0005 -0.21371 0.32553" quat="0.764842 0.644218 0 0" type="mesh" contype="0" conaffinity="0" group="1" density="0" rgba="0.898039 0.917647 0.929412 1" mesh="R_SHOULDER_Y_S"/>
    <geom pos="0.0005 -0.291248 0.176033" quat="0.764842 0.644218 0 0" type="mesh" contype="0" conaffinity="0" group="1" density="0" rgba="0.898039 0.917647 0.929412 1" mesh="R_ELBOW_Y_S"/>
    <geom pos="0.0005 -0.262763 0.041129" quat="0.764842 0.644218 0 0" type="mesh" contype="0" conaffinity="0" group="1" density="0" rgba="0.898039 0.917647 0.929412 1" mesh="R_WRIST_P_S"/>
    <geom pos="0.000590984 -0.329235 -0.0942223" quat="0.764842 0.644218 0 0" type="mesh" contype="0" conaffinity="0" group="1" density="0" rgba="0.898039 0.917647 0.929412 1" mesh="R_WRIST_Y_S"/>
    <geom pos="0.0315 -0.288377 -0.101496" quat="0.764842 0.644218 0 0" type="mesh" contype="0" conaffinity="0" group="1" density="0" rgba="0.752941 0.752941 0.752941 1" mesh="R_WRIST_R_S"/>
    <geom pos="0.0005 0 0.492" quat="1 0 0 0" type="mesh" contype="0" conaffinity="0" group="1" density="0" rgba="1 1 1 1" mesh="NECK_Y_S"/>
    <body name="L_HIP_P_S" pos="0 0.0945 -0.067">
      <inertial pos="0.012892 0.041367 1e-06" quat="0.627477 -0.000291411 -0.000475848 0.778635" mass="1.60224" diaginertia="0.00267399 0.00233509 0.00230796"/>
      <joint name="L_HIP_P" pos="0 0 0" axis="0 1 0" range="-3.14 3.14" limited="true" actuatorfrcrange="-267 267" class="leg_joint_param"/>
      <geom type="mesh" contype="0" conaffinity="0" group="1" density="0" rgba="0.898039 0.917647 0.929412 1" mesh="L_HIP_P_S"/>
      <geom size="0.075 0.075 0.15" pos="0 0.05 -0.16" type="box" rgba="0.898039 0.917647 0.929412 1"/>
      <body name="L_HIP_R_S" pos="0.058 0.044 0">
        <inertial pos="-0.052494 0.001116 -0.135556" quat="0.718827 0.0662956 0.0901577 0.686123" mass="2.12318" diaginertia="0.00835541 0.00788314 0.00311014"/>
        <joint name="L_HIP_R" pos="0 0 0" axis="1 0 0" range="-0.261 1.744" limited="true" actuatorfrcrange="-63 63" class="leg_joint_param"/>
        <geom type="mesh" contype="0" conaffinity="0" group="1" density="0" rgba="0.898039 0.917647 0.929412 1" mesh="L_HIP_R_S"/>
        <body name="L_HIP_Y_S" pos="-0.058 0 -0.1972">
          <inertial pos="0.001701 0.007194 -0.198857" quat="0.661595 0.00419875 0.0230361 0.749496" mass="3.31319" diaginertia="0.0181625 0.0177362 0.00657469"/>
          <joint name="L_HIP_Y" pos="0 0 0" axis="0 0 -1" range="-3.14 3.14" limited="true" actuatorfrcrange="-121 121" class="leg_joint_param"/>
          <geom type="mesh" contype="0" conaffinity="0" group="1" density="0" rgba="0.898039 0.917647 0.929412 1" mesh="L_HIP_Y_S"/>
          <body name="L_KNEE_P_S" pos="0 0.057 -0.2228">
            <inertial pos="-0.003673 -0.046279 -0.131966" quat="0.996344 -0.0215571 0.0588606 -0.0580409" mass="2.87226" diaginertia="0.0309237 0.0291387 0.00644882"/>
            <joint name="L_KNEE_P" pos="0 0 0" axis="0 1 0" range="-0.83 2.3" limited="true" actuatorfrcrange="-267 267" class="leg_joint_param"/>
            <geom type="mesh" contype="0" conaffinity="0" group="1" density="0" rgba="1 1 1 1" mesh="L_KNEE_P_S"/>
            <geom size="0.06 0.075 0.125" pos="0 -0.06 -0.2" type="box" rgba="1 1 1 1"/>
            <body name="L_ANKLE_P_S" pos="-0.032248 -0.058 -0.36859">
              <inertial pos="-0.006451 -0.006279 0.001685" quat="0.363576 0.67882 -0.304609 0.560562" mass="0.167704" diaginertia="0.000118849 8.01559e-05 7.10885e-05"/>
              <joint name="L_ANKLE_P" pos="0 0 0" axis="0 -1 0" range="-1.57 0.314" limited="true" actuatorfrcrange="-63 63" class="leg_joint_param"/>
              <geom type="mesh" contype="0" conaffinity="0" group="1" density="0" rgba="0.898039 0.917647 0.929412 1" mesh="L_ANKLE_P_S"/>
              <body name="L_ANKLE_R_S" pos="0.023 0 0">
                <inertial pos="0.019198 1e-06 -0.066833" quat="0.502366 0.497633 0.497632 0.502347" mass="2.58048" diaginertia="0.0148125 0.0131794 0.00501143"/>
                <joint name="L_ANKLE_R" pos="0 0 0" axis="1 0 0" range="-0.34 0.34" limited="true" actuatorfrcrange="-23 23" class="leg_joint_param"/>
                <geom type="mesh" contype="0" conaffinity="0" group="1" density="0" rgba="0.792157 0.819608 0.933333 1" mesh="L_ANKLE_R_S"/>
                <geom size="0.12 0.05 0.005" pos="0.02 0 -0.098" type="box" rgba="0.792157 0.819608 0.933333 1"/>
              </body>
            </body>
          </body>
        </body>
      </body>
    </body>
    <body name="R_HIP_P_S" pos="0 -0.0945 -0.067">
      <inertial pos="0.012246 -0.041162 1e-06" quat="0.77667 -0.00271576 -0.00217958 0.629898" mass="1.48677" diaginertia="0.00257663 0.00224167 0.00221078"/>
      <joint name="R_HIP_P" pos="0 0 0" axis="0 -1 0" range="-3.14 3.14" limited="true" actuatorfrcrange="-267 267" class="leg_joint_param"/>
      <geom type="mesh" contype="0" conaffinity="0" group="1" density="0" rgba="0.898039 0.917647 0.929412 1" mesh="R_HIP_P_S"/>
      <geom size="0.075 0.075 0.15" pos="0 -0.05 -0.16" type="box" rgba="0.898039 0.917647 0.929412 1"/>
      <body name="R_HIP_R_S" pos="0.058 -0.044 0">
        <inertial pos="-0.048002 -0.002026 -0.117145" quat="0.685206 0.0890741 0.0677358 0.719702" mass="1.16933" diaginertia="0.0067549 0.00628602 0.00252102"/>
        <joint name="R_HIP_R" pos="0 0 0" axis="1 0 0" range="-1.744 0.261" limited="true" actuatorfrcrange="-63 63"/>
        <geom type="mesh" contype="0" conaffinity="0" group="1" density="0" rgba="0.898039 0.917647 0.929412 1" mesh="R_HIP_R_S" class="leg_joint_param"/>
        <body name="R_HIP_Y_S" pos="-0.058 0 -0.1972">
          <inertial pos="0.001876 -0.007356 -0.1964" quat="0.750285 0.0225833 0.00423983 0.660715" mass="3.00568" diaginertia="0.0174642 0.0170509 0.00608184"/>
          <joint name="R_HIP_Y" pos="0 0 0" axis="0 0 -1" range="-3.14 3.14" limited="true" actuatorfrcrange="-121 121" class="leg_joint_param"/>
          <geom type="mesh" contype="0" conaffinity="0" group="1" density="0" rgba="0.898039 0.917647 0.929412 1" mesh="R_HIP_Y_S"/>
          <body name="R_KNEE_P_S" pos="0 -0.057 -0.2228">
            <inertial pos="-0.001129 0.044916 -0.124637" quat="0.998194 0.0145088 0.0494387 0.0309004" mass="2.65342" diaginertia="0.0273573 0.025749 0.00621402"/>
            <joint name="R_KNEE_P" pos="0 0 0" axis="0 -1 0" range="-2.3 0.83" limited="true" actuatorfrcrange="-267 267" class="leg_joint_param"/>
            <geom type="mesh" contype="0" conaffinity="0" group="1" density="0" rgba="0.898039 0.917647 0.929412 1" mesh="R_KNEE_P_S"/>
            <geom size="0.06 0.075 0.125" pos="0 0.06 -0.2" type="box" rgba="0.898039 0.917647 0.929412 1"/>
            <body name="R_ANKLE_P_S" pos="-0.032248 0.058 -0.36859">
              <inertial pos="-0.005285 0.0029 0.00138" quat="0.549092 0.54113 -0.453601 0.447127" mass="0.204699" diaginertia="0.000147897 0.000105132 7.78735e-05"/>
              <joint name="R_ANKLE_P" pos="0 0 0" axis="0 1 0" range="-0.314 1.57" limited="true" actuatorfrcrange="-63 63" class="leg_joint_param"/>
              <geom type="mesh" contype="0" conaffinity="0" group="1" density="0" rgba="0.898039 0.917647 0.929412 1" mesh="R_ANKLE_P_S"/>
              <body name="R_ANKLE_R_S" pos="0.023 0 0">
                <inertial pos="0.019038 -1e-06 -0.067145" quat="0.501909 0.498073 0.498073 0.50193" mass="2.57336" diaginertia="0.0147581 0.0131815 0.00495101"/>
                <joint name="R_ANKLE_R" pos="0 0 0" axis="1 0 0" range="-0.34 0.34" limited="true" actuatorfrcrange="-23 23" class="leg_joint_param"/>
                <geom type="mesh" contype="0" conaffinity="0" group="1" density="0" rgba="0.898039 0.917647 0.929412 1" mesh="R_ANKLE_R_S"/>
                <geom size="0.12 0.05 0.005" pos="0.02 0 -0.098" type="box" rgba="0.898039 0.917647 0.929412 1"/>
              </body>
            </body>
          </body>
        </body>
      </body>
    </body>
  </worldbody>
  <actuator>
    <motor name="left_leg_roll_joint" joint="L_HIP_P" gear="1" ctrllimited="true" ctrlrange="-200 200"/>
    <motor name="left_leg_yaw_joint" joint="L_HIP_R" gear="1" ctrllimited="true" ctrlrange="-200 200"/>
    <motor name="left_leg_pitch_joint" joint="L_HIP_Y" gear="1" ctrllimited="true" ctrlrange="-200 200"/>
    <motor name="left_knee_joint" joint="L_KNEE_P" gear="1" ctrllimited="true" ctrlrange="-200 200"/>
    <motor name="left_ankle_pitch_joint" joint="L_ANKLE_P" gear="1" ctrllimited="true" ctrlrange="-200 200"/>
    <motor name="left_ankle_roll_joint" joint="L_ANKLE_R" gear="1" ctrllimited="true" ctrlrange="-200 200"/>
    <motor name="right_leg_roll_joint" joint="R_HIP_P" gear="1" ctrllimited="true" ctrlrange="-200 200"/>
    <motor name="right_leg_yaw_joint" joint="R_HIP_R" gear="1" ctrllimited="true" ctrlrange="-200 200"/>
    <motor name="right_leg_pitch_joint" joint="R_HIP_Y" gear="1" ctrllimited="true" ctrlrange="-200 200"/>
    <motor name="right_knee_joint" joint="R_KNEE_P" gear="1" ctrllimited="true" ctrlrange="-200 200"/>
    <motor name="right_ankle_pitch_joint" joint="R_ANKLE_P" gear="1" ctrllimited="true" ctrlrange="-200 200"/>
    <motor name="right_ankle_roll_joint" joint="R_ANKLE_R" gear="1" ctrllimited="true" ctrlrange="-200 200"/>
  </actuator>

     <sensor>
        <actuatorpos name='left_leg_roll_joint_p'  actuator='left_leg_roll_joint' user='13'/>
        <actuatorpos name='left_leg_yaw_joint_p'  actuator='left_leg_yaw_joint' user='13'/>
        <actuatorpos name='left_leg_pitch_joint_p'  actuator='left_leg_pitch_joint' user='13'/>
        <actuatorpos name='left_knee_joint_p'  actuator='left_knee_joint' user='13'/>
        <actuatorpos name='left_ankle_pitch_joint_p'  actuator='left_ankle_pitch_joint' user='13'/>
        <actuatorpos name='left_ankle_roll_joint_p'  actuator='left_ankle_roll_joint' user='13'/>
        <actuatorpos name='right_leg_roll_joint_p'  actuator='right_leg_roll_joint' user='13'/>
        <actuatorpos name='right_leg_yaw_joint_p'  actuator='right_leg_yaw_joint' user='13'/>
        <actuatorpos name='right_leg_pitch_joint_p'  actuator='right_leg_pitch_joint' user='13'/>
        <actuatorpos name='right_knee_joint_p'  actuator='right_knee_joint' user='13'/>
        <actuatorpos name='right_ankle_pitch_joint_p'  actuator='right_ankle_pitch_joint' user='13'/>
        <actuatorpos name='right_ankle_roll_joint_p'  actuator='right_ankle_roll_joint' user='13'/>

        <actuatorvel name='left_leg_roll_joint_v'  actuator='left_leg_roll_joint' user='13'/>
        <actuatorvel name='left_leg_yaw_joint_v'  actuator='left_leg_yaw_joint' user='13'/>
        <actuatorvel name='left_leg_pitch_joint_v'  actuator='left_leg_pitch_joint' user='13'/>
        <actuatorvel name='left_knee_joint_v'  actuator='left_knee_joint' user='13'/>
        <actuatorvel name='left_ankle_pitch_joint_v'  actuator='left_ankle_pitch_joint' user='13'/>
        <actuatorvel name='left_ankle_roll_joint_v'  actuator='left_ankle_roll_joint' user='13'/>
        <actuatorvel name='right_leg_roll_joint_v'  actuator='right_leg_roll_joint' user='13'/>
        <actuatorvel name='right_leg_yaw_joint_v'  actuator='right_leg_yaw_joint' user='13'/>
        <actuatorvel name='right_leg_pitch_joint_v'  actuator='right_leg_pitch_joint' user='13'/>
        <actuatorvel name='right_knee_joint_v'  actuator='right_knee_joint' user='13'/>
        <actuatorvel name='right_ankle_pitch_joint_v'  actuator='right_ankle_pitch_joint' user='13'/>
        <actuatorvel name='right_ankle_roll_joint_v'  actuator='right_ankle_roll_joint' user='13'/>

        <actuatorfrc name='left_leg_roll_joint_f'  actuator='left_leg_roll_joint' user='13' noise='1e-3'/>
        <actuatorfrc name='left_leg_yaw_joint_f'  actuator='left_leg_yaw_joint' user='13' noise='1e-3'/>
        <actuatorfrc name='left_leg_pitch_joint_f'  actuator='left_leg_pitch_joint' user='13' noise='1e-3'/>
        <actuatorfrc name='left_knee_joint_f'  actuator='left_knee_joint' user='13' noise='1e-3'/>
        <actuatorfrc name='left_ankle_pitch_joint_f'  actuator='left_ankle_pitch_joint' user='13' noise='1e-3'/>
        <actuatorfrc name='left_ankle_roll_joint_f'  actuator='left_ankle_roll_joint' user='13' noise='1e-3'/>
        <actuatorfrc name='right_leg_roll_joint_f'  actuator='right_leg_roll_joint' user='13' noise='1e-3'/>
        <actuatorfrc name='right_leg_yaw_joint_f'  actuator='right_leg_yaw_joint' user='13' noise='1e-3'/>
        <actuatorfrc name='right_leg_pitch_joint_f'  actuator='right_leg_pitch_joint' user='13' noise='1e-3'/>
        <actuatorfrc name='right_knee_joint_f'  actuator='right_knee_joint' user='13' noise='1e-3'/>
        <actuatorfrc name='right_ankle_pitch_joint_f'  actuator='right_ankle_pitch_joint' user='13' noise='1e-3'/>
        <actuatorfrc name='right_ankle_roll_joint_f'  actuator='right_ankle_roll_joint' user='13' noise='1e-3'/>


        <framequat     name='orientation' objtype='site' noise='0.001' objname='imu'/>
        <framepos     name='position' objtype='site' noise='0.001' objname='imu'/>
        <gyro          name='angular-velocity'    site='imu' noise='0.005' cutoff='34.9'/>
        <velocimeter   name='linear-velocity'     site='imu' noise='0.001' cutoff='30'/>
        <accelerometer name='linear-acceleration' site='imu' noise='0.005' cutoff='157'/>
        <magnetometer  name='magnetometer'        site='imu'/>

    </sensor>

</mujoco>
