<mujoco model="T170-V2.1-A0-mass">
  <default>
    <default class="robot">
      <default class="motor">
        <joint />
        <motor />
      </default>
      <default class="visual">
        <geom material="visualgeom" contype="0" conaffinity="0" group="2" />
      </default>
      <default class="collision">
        <geom material="collision_material" condim="3" contype="0" conaffinity="1" priority="1" group="1" solref="0.005 1" friction="1 0.01 0.01" />
        <equality solimp="0.99 0.999 1e-05" solref="0.005 1" />
      </default>
    </default>
  </default>

  <compiler angle="radian" />

  <asset>
    <material name="" rgba="1 1 1 1" />
    <material name="default_material" rgba="0.7 0.7 0.7 1" />
    <material name="collision_material" rgba="1.0 0.28 0.1 0.9" />
    <mesh name="BASE_S.STL" file="meshes/BASE_S.STL" />
    <mesh name="L_HIP_P_S.STL" file="meshes/L_HIP_P_S.STL" />
    <mesh name="L_HIP_R_S.STL" file="meshes/L_HIP_R_S.STL" />
    <mesh name="L_HIP_Y_S.STL" file="meshes/L_HIP_Y_S.STL" />
    <mesh name="L_KNEE_P_S.STL" file="meshes/L_KNEE_P_S.STL" />
    <mesh name="L_ANKLE_P_S.STL" file="meshes/L_ANKLE_P_S.STL" />
    <mesh name="L_ANKLE_R_S.STL" file="meshes/L_ANKLE_R_S.STL" />
    <mesh name="R_HIP_P_S.STL" file="meshes/R_HIP_P_S.STL" />
    <mesh name="R_HIP_R_S.STL" file="meshes/R_HIP_R_S.STL" />
    <mesh name="R_HIP_Y_S.STL" file="meshes/R_HIP_Y_S.STL" />
    <mesh name="R_KNEE_P_S.STL" file="meshes/R_KNEE_P_S.STL" />
    <mesh name="R_ANKLE_P_S.STL" file="meshes/R_ANKLE_P_S.STL" />
    <mesh name="R_ANKLE_R_S.STL" file="meshes/R_ANKLE_R_S.STL" />
    <mesh name="WAIST_Y_S.STL" file="meshes/WAIST_Y_S.STL" />
    <mesh name="WAIST_R_S.STL" file="meshes/WAIST_R_S.STL" />
    <mesh name="WAIST_P_S.STL" file="meshes/WAIST_P_S.STL" />
    <mesh name="L_SHOULDER_P_S.STL" file="meshes/L_SHOULDER_P_S.STL" />
    <mesh name="L_SHOULDER_R_S.STL" file="meshes/L_SHOULDER_R_S.STL" />
    <mesh name="L_SHOULDER_Y_S.STL" file="meshes/L_SHOULDER_Y_S.STL" />
    <mesh name="L_ELBOW_Y_S.STL" file="meshes/L_ELBOW_Y_S.STL" />
    <mesh name="L_WRIST_P_S.STL" file="meshes/L_WRIST_P_S.STL" />
    <mesh name="L_WRIST_Y_S.STL" file="meshes/L_WRIST_Y_S.STL" />
    <mesh name="L_WRIST_R_S.STL" file="meshes/L_WRIST_R_S.STL" />
    <mesh name="R_SHOULDER_P_S.STL" file="meshes/R_SHOULDER_P_S.STL" />
    <mesh name="R_SHOULDER_R_S.STL" file="meshes/R_SHOULDER_R_S.STL" />
    <mesh name="R_SHOULDER_Y_S.STL" file="meshes/R_SHOULDER_Y_S.STL" />
    <mesh name="R_ELBOW_Y_S.STL" file="meshes/R_ELBOW_Y_S.STL" />
    <mesh name="R_WRIST_P_S.STL" file="meshes/R_WRIST_P_S.STL" />
    <mesh name="R_WRIST_Y_S.STL" file="meshes/R_WRIST_Y_S.STL" />
    <mesh name="R_WRIST_R_S.STL" file="meshes/R_WRIST_R_S.STL" />
    <mesh name="NECK_Y_S.STL" file="meshes/NECK_Y_S.STL" />
  </asset>

  <worldbody>
    <body name="world" pos="0.00000000 0.00000000 0.85559000" quat="1 0 0 0" childclass="robot">
      <freejoint name="floating_base" />
      <body name="BASE_S" pos="0 0 0" quat="1 0 0 0">
        <inertial pos="-6.500000000000001e-05 1e-06 -0.045045" quat="1.0 0.0 0.0 0.0" mass="5.294303" diaginertia="0.024433582611999998 0.016612578556 0.016497152209000002" />
        <geom name="BASE_S_collision" pos="0 0 0" quat="1.0 0.0 0.0 0.0" type="mesh" mesh="BASE_S.STL" class="collision" />
        <geom name="BASE_S_visual" pos="0 0 0" quat="1.0 0.0 0.0 0.0" material="" type="mesh" mesh="BASE_S.STL" class="visual" />
        <body name="L_HIP_P_S" pos="0 0.0945 -0.067" quat="1.0 0.0 0.0 0.0">
          <joint name="L_HIP_P" type="hinge" ref="0.0" class="motor" range="-3.14 3.14" axis="0 1 0" />
          <inertial pos="0.012891999999999999 0.041366999999999994 1e-06" quat="1.0 0.0 0.0 0.0" mass="1.60224" diaginertia="0.002350403566 0.0026586781120000002 0.0023079587030000004" />
          <geom name="L_HIP_P_S_collision" pos="0 0 0" quat="1.0 0.0 0.0 0.0" type="mesh" mesh="L_HIP_P_S.STL" class="collision" />
          <geom name="L_HIP_P_S_visual" pos="0 0 0" quat="1.0 0.0 0.0 0.0" material="" type="mesh" mesh="L_HIP_P_S.STL" class="visual" />
          <body name="L_HIP_R_S" pos="0.058 0.044 0" quat="1.0 0.0 0.0 0.0">
            <joint name="L_HIP_R" type="hinge" ref="0.0" class="motor" range="-0.261 1.744" axis="1 0 0" />
            <inertial pos="-0.052494 0.001116 -0.135556" quat="1.0 0.0 0.0 0.0" mass="2.123182" diaginertia="0.007651730159 0.008350014866 0.003346951658" />
            <geom name="L_HIP_R_S_collision" pos="0 0 0" quat="1.0 0.0 0.0 0.0" type="mesh" mesh="L_HIP_R_S.STL" class="collision" />
            <geom name="L_HIP_R_S_visual" pos="0 0 0" quat="1.0 0.0 0.0 0.0" material="" type="mesh" mesh="L_HIP_R_S.STL" class="visual" />
            <body name="L_HIP_Y_S" pos="-0.058 0 -0.1972" quat="1.0 0.0 0.0 0.0">
              <joint name="L_HIP_Y" type="hinge" ref="0.0" class="motor" range="-3.14 3.14" axis="0 0 1" />
              <inertial pos="0.001701 0.007194 -0.198857" quat="1.0 0.0 0.0 0.0" mass="3.313186" diaginertia="0.017727672841 0.018146293801 0.006599402896" />
              <geom name="L_HIP_Y_S_collision" pos="0 0 0" quat="1.0 0.0 0.0 0.0" type="mesh" mesh="L_HIP_Y_S.STL" class="collision" />
              <geom name="L_HIP_Y_S_visual" pos="0 0 0" quat="1.0 0.0 0.0 0.0" material="" type="mesh" mesh="L_HIP_Y_S.STL" class="visual" />
              <body name="L_KNEE_P_S" pos="0 0.057 -0.2228" quat="1.0 0.0 0.0 0.0">
                <joint name="L_KNEE_P" type="hinge" ref="0.0" class="motor" range="-0.83 2.3" axis="0 1 0" />
                <inertial pos="0.000631 -0.043392 -0.119632" quat="1.0 0.0 0.0 0.0" mass="2.644024" diaginertia="0.025178069248 0.023717199600000002 0.006274894778" />
                <geom name="L_KNEE_P_S_collision" pos="0 0 0" quat="1.0 0.0 0.0 0.0" type="mesh" mesh="L_KNEE_P_S.STL" class="collision" />
                <geom name="L_KNEE_P_S_visual" pos="0 0 0" quat="1.0 0.0 0.0 0.0" material="" type="mesh" mesh="L_KNEE_P_S.STL" class="visual" />
                <body name="L_ANKLE_P_S" pos="-0.032248 -0.058 -0.36859" quat="1.0 0.0 0.0 0.0">
                  <joint name="L_ANKLE_P" type="hinge" ref="0.0" class="motor" range="-0.314 1.57" axis="0 1 0" />
                  <inertial pos="-0.0051920000000000004 -0.003552 0.001356" quat="1.0 0.0 0.0 0.0" mass="0.208363" diaginertia="0.000112416441 7.9570327e-05 0.00015223668599999998" />
                  <geom name="L_ANKLE_P_S_collision" pos="0 0 0" quat="1.0 0.0 0.0 0.0" type="mesh" mesh="L_ANKLE_P_S.STL" class="collision" />
                  <geom name="L_ANKLE_P_S_visual" pos="0 0 0" quat="1.0 0.0 0.0 0.0" material="" type="mesh" mesh="L_ANKLE_P_S.STL" class="visual" />
                  <body name="L_ANKLE_R_S" pos="0.023 0 0" quat="1.0 0.0 0.0 0.0">
                    <joint name="L_ANKLE_R" type="hinge" ref="0.0" class="motor" range="-0.34 0.34" axis="1 0 0" />
                    <inertial pos="0.016272 2e-06 -0.054217" quat="1.0 0.0 0.0 0.0" mass="1.670521" diaginertia="0.0034800322570000004 0.008485757659 0.006910381204" />
                    <geom name="L_ANKLE_R_S_collision" pos="0 0 0" quat="1.0 0.0 0.0 0.0" type="mesh" mesh="L_ANKLE_R_S.STL" class="collision" />
                    <geom name="L_ANKLE_R_S_visual" pos="0 0 0" quat="1.0 0.0 0.0 0.0" material="" type="mesh" mesh="L_ANKLE_R_S.STL" class="visual" />
                  </body>
                </body>
              </body>
            </body>
          </body>
        </body>
        <body name="R_HIP_P_S" pos="0 -0.0945 -0.067" quat="1.0 0.0 0.0 0.0">
          <joint name="R_HIP_P" type="hinge" ref="0.0" class="motor" range="-3.14 3.14" axis="0 1 0" />
          <inertial pos="0.012891999999999999 -0.041366999999999994 1e-06" quat="1.0 0.0 0.0 0.0" mass="1.602236" diaginertia="0.002350387347 0.002658669353 0.002307962669" />
          <geom name="R_HIP_P_S_collision" pos="0 0 0" quat="1.0 0.0 0.0 0.0" type="mesh" mesh="R_HIP_P_S.STL" class="collision" />
          <geom name="R_HIP_P_S_visual" pos="0 0 0" quat="1.0 0.0 0.0 0.0" material="" type="mesh" mesh="R_HIP_P_S.STL" class="visual" />
          <body name="R_HIP_R_S" pos="0.058 -0.044 0" quat="1.0 0.0 0.0 0.0">
            <joint name="R_HIP_R" type="hinge" ref="0.0" class="motor" range="-1.744 0.261" axis="1 0 0" />
            <inertial pos="-0.052494 -0.001116 -0.135556" quat="1.0 0.0 0.0 0.0" mass="2.123172" diaginertia="0.007651678789 0.008350089033 0.00334698021" />
            <geom name="R_HIP_R_S_collision" pos="0 0 0" quat="1.0 0.0 0.0 0.0" type="mesh" mesh="R_HIP_R_S.STL" class="collision" />
            <geom name="R_HIP_R_S_visual" pos="0 0 0" quat="1.0 0.0 0.0 0.0" material="" type="mesh" mesh="R_HIP_R_S.STL" class="visual" />
            <body name="R_HIP_Y_S" pos="-0.058 0 -0.1972" quat="1.0 0.0 0.0 0.0">
              <joint name="R_HIP_Y" type="hinge" ref="0.0" class="motor" range="-3.14 3.14" axis="0 0 1" />
              <inertial pos="0.001702 -0.007193 -0.198851" quat="1.0 0.0 0.0 0.0" mass="3.313288" diaginertia="0.017731261837000002 0.018149824549 0.006599775929" />
              <geom name="R_HIP_Y_S_collision" pos="0 0 0" quat="1.0 0.0 0.0 0.0" type="mesh" mesh="R_HIP_Y_S.STL" class="collision" />
              <geom name="R_HIP_Y_S_visual" pos="0 0 0" quat="1.0 0.0 0.0 0.0" material="" type="mesh" mesh="R_HIP_Y_S.STL" class="visual" />
              <body name="R_KNEE_P_S" pos="0 -0.057 -0.2228" quat="1.0 0.0 0.0 0.0">
                <joint name="R_KNEE_P" type="hinge" ref="0.0" class="motor" range="-0.83 2.3" axis="0 1 0" />
                <inertial pos="0.0006360000000000001 0.04339 -0.119639" quat="1.0 0.0 0.0 0.0" mass="2.644373" diaginertia="0.025184545238 0.023724867226 0.006275270264" />
                <geom name="R_KNEE_P_S_collision" pos="0 0 0" quat="1.0 0.0 0.0 0.0" type="mesh" mesh="R_KNEE_P_S.STL" class="collision" />
                <geom name="R_KNEE_P_S_visual" pos="0 0 0" quat="1.0 0.0 0.0 0.0" material="" type="mesh" mesh="R_KNEE_P_S.STL" class="visual" />
                <body name="R_ANKLE_P_S" pos="-0.032248 0.058 -0.36859" quat="1.0 0.0 0.0 0.0">
                  <joint name="R_ANKLE_P" type="hinge" ref="0.0" class="motor" range="-0.314 1.57" axis="0 1 0" />
                  <inertial pos="-0.005285 0.0029 0.00138" quat="1.0 0.0 0.0 0.0" mass="0.20469900000000002" diaginertia="0.000106648193 7.7879228e-05 0.00014637474900000002" />
                  <geom name="R_ANKLE_P_S_collision" pos="0 0 0" quat="1.0 0.0 0.0 0.0" type="mesh" mesh="R_ANKLE_P_S.STL" class="collision" />
                  <geom name="R_ANKLE_P_S_visual" pos="0 0 0" quat="1.0 0.0 0.0 0.0" material="" type="mesh" mesh="R_ANKLE_P_S.STL" class="visual" />
                  <body name="R_ANKLE_R_S" pos="0.023 0 0" quat="1.0 0.0 0.0 0.0">
                    <joint name="R_ANKLE_R" type="hinge" ref="0.0" class="motor" range="-0.34 0.34" axis="1 0 0" />
                    <inertial pos="0.016272 -2e-06 -0.054217" quat="1.0 0.0 0.0 0.0" mass="1.67052" diaginertia="0.003480032579 0.00848575142 0.00691037666" />
                    <geom name="R_ANKLE_R_S_collision" pos="0 0 0" quat="1.0 0.0 0.0 0.0" type="mesh" mesh="R_ANKLE_R_S.STL" class="collision" />
                    <geom name="R_ANKLE_R_S_visual" pos="0 0 0" quat="1.0 0.0 0.0 0.0" material="" type="mesh" mesh="R_ANKLE_R_S.STL" class="visual" />
                  </body>
                </body>
              </body>
            </body>
          </body>
        </body>
        <body name="WAIST_Y_S" pos="0 0 0" quat="1.0 0.0 0.0 0.0">
          <joint name="WAIST_Y" type="hinge" ref="0.0" class="motor" range="-3.14 3.14" axis="0 0 -1" />
          <inertial pos="-0.070117 0.0 0.109774" quat="1.0 0.0 0.0 0.0" mass="1.49971" diaginertia="0.002892639151 0.005042794342 0.003666403193" />
          <geom name="WAIST_Y_S_collision" pos="0 0 0" quat="1.0 0.0 0.0 0.0" type="mesh" mesh="WAIST_Y_S.STL" class="collision" />
          <geom name="WAIST_Y_S_visual" pos="0 0 0" quat="1.0 0.0 0.0 0.0" material="" type="mesh" mesh="WAIST_Y_S.STL" class="visual" />
          <body name="WAIST_R_S" pos="-0.0495 0 0.127" quat="1.0 0.0 0.0 0.0">
            <joint name="WAIST_R" type="hinge" ref="0.0" class="motor" range="-0.61 0.61" axis="1 0 0" />
            <inertial pos="0.047638 0.0060609999999999995 0.0" quat="1.0 0.0 0.0 0.0" mass="1.3648900000000002" diaginertia="0.0013838946489999999 0.001586091616 0.001453676082" />
            <geom name="WAIST_R_S_collision" pos="0 0 0" quat="1.0 0.0 0.0 0.0" type="mesh" mesh="WAIST_R_S.STL" class="collision" />
            <geom name="WAIST_R_S_visual" pos="0 0 0" quat="1.0 0.0 0.0 0.0" material="" type="mesh" mesh="WAIST_R_S.STL" class="visual" />
            <body name="WAIST_P_S" pos="0.0495 0.0465 0" quat="1.0 0.0 0.0 0.0">
              <joint name="WAIST_P" type="hinge" ref="0.0" class="motor" range="-0.244 0.523" axis="0 1 0" />
              <inertial pos="0.00211 -0.046560000000000004 0.245727" quat="1.0 0.0 0.0 0.0" mass="11.080885" diaginertia="0.11949464686200001 0.08538231980699999 0.065471635027" />
              <geom name="WAIST_P_S_collision" pos="0 0 0" quat="1.0 0.0 0.0 0.0" type="mesh" mesh="WAIST_P_S.STL" class="collision" />
              <geom name="WAIST_P_S_visual" pos="0 0 0" quat="1.0 0.0 0.0 0.0" material="" type="mesh" mesh="WAIST_P_S.STL" class="visual" />
              <body name="L_SHOULDER_P_S" pos="0.0005 0.0775 0.336" quat="1.0 0.0 0.0 0.0">
                <joint name="L_SHOULDER_P" type="hinge" ref="0.0" class="motor" range="-3.14 3.14" axis="0 1 0" />
                <inertial pos="0.011526 0.059677999999999995 0.0" quat="1.0 0.0 0.0 0.0" mass="1.444881" diaginertia="0.001949609421 0.0015971993259999999 0.001979001997" />
                <geom name="L_SHOULDER_P_S_collision" pos="0 0 0" quat="1.0 0.0 0.0 0.0" type="mesh" mesh="L_SHOULDER_P_S.STL" class="collision" />
                <geom name="L_SHOULDER_P_S_visual" pos="0 0 0" quat="1.0 0.0 0.0 0.0" material="" type="mesh" mesh="L_SHOULDER_P_S.STL" class="visual" />
                <body name="L_SHOULDER_R_S" pos="0.054 0.066 0" quat="1.0 0.0 0.0 0.0">
                  <joint name="L_SHOULDER_R" type="hinge" ref="0.0" class="motor" range="-1.57 1.57" axis="1 0 0" />
                  <inertial pos="-0.050103 0.088587 0.000207" quat="1.0 0.0 0.0 0.0" mass="1.014451" diaginertia="0.002349561045 0.0011315652760000002 0.002633113913" />
                  <geom name="L_SHOULDER_R_S_collision" pos="0 0 0" quat="1.0 0.0 0.0 0.0" type="mesh" mesh="L_SHOULDER_R_S.STL" class="collision" />
                  <geom name="L_SHOULDER_R_S_visual" pos="0 0 0" quat="1.0 0.0 0.0 0.0" material="" type="mesh" mesh="L_SHOULDER_R_S.STL" class="visual" />
                  <body name="L_SHOULDER_Y_S" pos="-0.054 0.1395 0" quat="1.0 0.0 0.0 0.0">
                    <joint name="L_SHOULDER_Y" type="hinge" ref="0.0" class="motor" range="-3.14 3.14" axis="0 1 0" />
                    <inertial pos="-0.002242 0.128183 0.013930999999999999" quat="1.0 0.0 0.0 0.0" mass="1.09809" diaginertia="0.0043556597410000005 0.001024987862 0.00415956279" />
                    <geom name="L_SHOULDER_Y_S_collision" pos="0 0 0" quat="1.0 0.0 0.0 0.0" type="mesh" mesh="L_SHOULDER_Y_S.STL" class="collision" />
                    <geom name="L_SHOULDER_Y_S_visual" pos="0 0 0" quat="1.0 0.0 0.0 0.0" material="" type="mesh" mesh="L_SHOULDER_Y_S.STL" class="visual" />
                    <body name="L_ELBOW_Y_S" pos="0 0.1605 0.051" quat="1.0 0.0 0.0 0.0">
                      <joint name="L_ELBOW_Y" type="hinge" ref="0.0" class="motor" range="-2.4 0.87" axis="0 0 1" />
                      <inertial pos="-0.000772 0.079344 -0.047655" quat="1.0 0.0 0.0 0.0" mass="0.71509" diaginertia="0.0015319294410000002 0.0008379935259999999 0.001338291607" />
                      <geom name="L_ELBOW_Y_S_collision" pos="0 0 0" quat="1.0 0.0 0.0 0.0" type="mesh" mesh="L_ELBOW_Y_S.STL" class="collision" />
                      <geom name="L_ELBOW_Y_S_visual" pos="0 0 0" quat="1.0 0.0 0.0 0.0" material="" type="mesh" mesh="L_ELBOW_Y_S.STL" class="visual" />
                      <body name="L_WRIST_P_S" pos="0 0.1281 -0.051" quat="1.0 0.0 0.0 0.0">
                        <joint name="L_WRIST_P" type="hinge" ref="0.0" class="motor" range="-3.14 3.14" axis="0 1 0" />
                        <inertial pos="-2e-05 0.051770000000000004 0.015054" quat="1.0 0.0 0.0 0.0" mass="0.787608" diaginertia="0.0018731701289999999 0.000729715644 0.001676076534" />
                        <geom name="L_WRIST_P_S_collision" pos="0 0 0" quat="1.0 0.0 0.0 0.0" type="mesh" mesh="L_WRIST_P_S.STL" class="collision" />
                        <geom name="L_WRIST_P_S_visual" pos="0 0 0" quat="1.0 0.0 0.0 0.0" material="" type="mesh" mesh="L_WRIST_P_S.STL" class="visual" />
                        <body name="L_WRIST_Y_S" pos="9.0984E-05 0.14468 0.0425" quat="1.0 0.0 0.0 0.0">
                          <joint name="L_WRIST_Y" type="hinge" ref="0.0" class="motor" range="-0.69 0.69" axis="0 0 1" />
                          <inertial pos="-0.0007840000000000001 0.00022600000000000002 -0.037801" quat="1.0 0.0 0.0 0.0" mass="0.38146199999999997" diaginertia="0.000182718093 0.00021651213 0.000172529454" />
                          <geom name="L_WRIST_Y_S_collision" pos="0 0 0" quat="1.0 0.0 0.0 0.0" type="mesh" mesh="L_WRIST_Y_S.STL" class="collision" />
                          <geom name="L_WRIST_Y_S_visual" pos="0 0 0" quat="1.0 0.0 0.0 0.0" material="" type="mesh" mesh="L_WRIST_Y_S.STL" class="visual" />
                          <body name="L_WRIST_R_S" pos="0.030909 0.00022307 -0.0415" quat="1.0 0.0 0.0 0.0">
                            <joint name="L_WRIST_R" type="hinge" ref="0.0" class="motor" range="-2.35 0.348" axis="1 0 0" />
                            <inertial pos="-0.011640000000000001 0.118483 -0.0036030000000000003" quat="1.0 0.0 0.0 0.0" mass="0.553221" diaginertia="0.001536982549 0.000603820302 0.001875863069" />
                            <geom name="L_WRIST_R_S_collision" pos="0 0 0" quat="1.0 0.0 0.0 0.0" type="mesh" mesh="L_WRIST_R_S.STL" class="collision" />
                            <geom name="L_WRIST_R_S_visual" pos="0 0 0" quat="1.0 0.0 0.0 0.0" material="" type="mesh" mesh="L_WRIST_R_S.STL" class="visual" />
                          </body>
                        </body>
                      </body>
                    </body>
                  </body>
                </body>
              </body>
              <body name="R_SHOULDER_P_S" pos="0.0005 -0.1705 0.336" quat="1.0 0.0 0.0 0.0">
                <joint name="R_SHOULDER_P" type="hinge" ref="0.0" class="motor" range="-3.14 3.14" axis="0 -1 0" />
                <inertial pos="0.011141999999999999 -0.05972 0.0" quat="1.0 0.0 0.0 0.0" mass="1.4546679999999999" diaginertia="0.001954186556 0.0016309633759999998 0.002013157615" />
                <geom name="R_SHOULDER_P_S_collision" pos="0 0 0" quat="1.0 0.0 0.0 0.0" type="mesh" mesh="R_SHOULDER_P_S.STL" class="collision" />
                <geom name="R_SHOULDER_P_S_visual" pos="0 0 0" quat="1.0 0.0 0.0 0.0" material="" type="mesh" mesh="R_SHOULDER_P_S.STL" class="visual" />
                <body name="R_SHOULDER_R_S" pos="0.054 -0.066 0" quat="1.0 0.0 0.0 0.0">
                  <joint name="R_SHOULDER_R" type="hinge" ref="0.0" class="motor" range="-1.57 1.57" axis="1 0 0" />
                  <inertial pos="-0.050103 -0.088586 0.000207" quat="1.0 0.0 0.0 0.0" mass="1.014496" diaginertia="0.002349644494 0.001131637812 0.002633199673" />
                  <geom name="R_SHOULDER_R_S_collision" pos="0 0 0" quat="1.0 0.0 0.0 0.0" type="mesh" mesh="R_SHOULDER_R_S.STL" class="collision" />
                  <geom name="R_SHOULDER_R_S_visual" pos="0 0 0" quat="1.0 0.0 0.0 0.0" material="" type="mesh" mesh="R_SHOULDER_R_S.STL" class="visual" />
                  <body name="R_SHOULDER_Y_S" pos="-0.054 -0.1395 0" quat="1.0 0.0 0.0 0.0">
                    <joint name="R_SHOULDER_Y" type="hinge" ref="0.0" class="motor" range="-3.14 3.14" axis="0 -1 0" />
                    <inertial pos="-0.0022429999999999998 -0.128186 0.01393" quat="1.0 0.0 0.0 0.0" mass="1.098095" diaginertia="0.004355094775 0.00102492432 0.004159196881" />
                    <geom name="R_SHOULDER_Y_S_collision" pos="0 0 0" quat="1.0 0.0 0.0 0.0" type="mesh" mesh="R_SHOULDER_Y_S.STL" class="collision" />
                    <geom name="R_SHOULDER_Y_S_visual" pos="0 0 0" quat="1.0 0.0 0.0 0.0" material="" type="mesh" mesh="R_SHOULDER_Y_S.STL" class="visual" />
                    <body name="R_ELBOW_Y_S" pos="0 -0.1605 0.051" quat="1.0 0.0 0.0 0.0">
                      <joint name="R_ELBOW_Y" type="hinge" ref="0.0" class="motor" range="-0.87 2.4" axis="0 0 1" />
                      <inertial pos="-0.0007700000000000001 -0.079347 -0.047652" quat="1.0 0.0 0.0 0.0" mass="0.71504" diaginertia="0.0015318807949999999 0.000837959623 0.0013381406899999999" />
                      <geom name="R_ELBOW_Y_S_collision" pos="0 0 0" quat="1.0 0.0 0.0 0.0" type="mesh" mesh="R_ELBOW_Y_S.STL" class="collision" />
                      <geom name="R_ELBOW_Y_S_visual" pos="0 0 0" quat="1.0 0.0 0.0 0.0" material="" type="mesh" mesh="R_ELBOW_Y_S.STL" class="visual" />
                      <body name="R_WRIST_P_S" pos="0 -0.1281 -0.051" quat="1.0 0.0 0.0 0.0">
                        <joint name="R_WRIST_P" type="hinge" ref="0.0" class="motor" range="-3.14 3.14" axis="0 -1 0" />
                        <inertial pos="0.0 -0.051778 0.015023" quat="1.0 0.0 0.0 0.0" mass="0.7868890000000001" diaginertia="0.001872273263 0.000729272968 0.001675513763" />
                        <geom name="R_WRIST_P_S_collision" pos="0 0 0" quat="1.0 0.0 0.0 0.0" type="mesh" mesh="R_WRIST_P_S.STL" class="collision" />
                        <geom name="R_WRIST_P_S_visual" pos="0 0 0" quat="1.0 0.0 0.0 0.0" material="" type="mesh" mesh="R_WRIST_P_S.STL" class="visual" />
                        <body name="R_WRIST_Y_S" pos="9.0984E-05 -0.14468 0.0425" quat="1.0 0.0 0.0 0.0">
                          <joint name="R_WRIST_Y" type="hinge" ref="0.0" class="motor" range="-0.69 0.69" axis="0 0 1" />
                          <inertial pos="-0.0007840000000000001 -0.00022600000000000002 -0.037801" quat="1.0 0.0 0.0 0.0" mass="0.38146199999999997" diaginertia="0.000182718093 0.00021651213 0.000172529454" />
                          <geom name="R_WRIST_Y_S_collision" pos="0 0 0" quat="1.0 0.0 0.0 0.0" type="mesh" mesh="R_WRIST_Y_S.STL" class="collision" />
                          <geom name="R_WRIST_Y_S_visual" pos="0 0 0" quat="1.0 0.0 0.0 0.0" material="" type="mesh" mesh="R_WRIST_Y_S.STL" class="visual" />
                          <body name="R_WRIST_R_S" pos="0.030909 -0.00022307 -0.0415" quat="1.0 0.0 0.0 0.0">
                            <joint name="R_WRIST_R" type="hinge" ref="0.0" class="motor" range="-0.348 2.35" axis="1 0 0" />
                            <inertial pos="-0.011723 -0.118518 -0.0027440000000000003" quat="1.0 0.0 0.0 0.0" mass="0.553221" diaginertia="0.001538629013 0.0006011281409999999 0.001871429419" />
                            <geom name="R_WRIST_R_S_collision" pos="0 0 0" quat="1.0 0.0 0.0 0.0" type="mesh" mesh="R_WRIST_R_S.STL" class="collision" />
                            <geom name="R_WRIST_R_S_visual" pos="0 0 0" quat="1.0 0.0 0.0 0.0" material="" type="mesh" mesh="R_WRIST_R_S.STL" class="visual" />
                          </body>
                        </body>
                      </body>
                    </body>
                  </body>
                </body>
              </body>
              <body name="NECK_Y_S" pos="0.0005 -0.0465 0.365" quat="1.0 0.0 0.0 0.0">
                <joint name="NECK_Y" type="hinge" ref="0.0" class="motor" range="-3.14 3.14" axis="0 0 1" />
                <inertial pos="0.0261 0.00014000000000000001 0.18196700000000002" quat="1.0 0.0 0.0 0.0" mass="2.50061" diaginertia="0.014941218582000001 0.017071265236000003 0.009101680967" />
                <geom name="NECK_Y_S_collision" pos="0 0 0" quat="1.0 0.0 0.0 0.0" type="mesh" mesh="NECK_Y_S.STL" class="collision" />
                <geom name="NECK_Y_S_visual" pos="0 0 0" quat="1.0 0.0 0.0 0.0" material="" type="mesh" mesh="NECK_Y_S.STL" class="visual" />
              </body>
            </body>
          </body>
        </body>
      </body>
      <site name="world_site" pos="0 0 0" quat="1 0 0 0" />
      <camera name="front_camera" mode="track" fovy="90.0" quat="4.329780281177467e-17 4.329780281177466e-17 0.7071067811865475 0.7071067811865476" pos="0.0 2.0 0.5" />
      <camera name="side_camera" mode="track" fovy="90.0" quat="-0.5 -0.4999999999999999 0.5 0.5000000000000001" pos="-2.0 0.0 0.5" />
    </body>
  </worldbody>

  <actuator>
    <motor name="L_HIP_P_ctrl" joint="L_HIP_P" class="motor" />
    <motor name="L_HIP_R_ctrl" joint="L_HIP_R" class="motor" />
    <motor name="L_HIP_Y_ctrl" joint="L_HIP_Y" class="motor" />
    <motor name="L_KNEE_P_ctrl" joint="L_KNEE_P" class="motor" />
    <motor name="L_ANKLE_P_ctrl" joint="L_ANKLE_P" class="motor" />
    <motor name="L_ANKLE_R_ctrl" joint="L_ANKLE_R" class="motor" />
    <motor name="R_HIP_P_ctrl" joint="R_HIP_P" class="motor" />
    <motor name="R_HIP_R_ctrl" joint="R_HIP_R" class="motor" />
    <motor name="R_HIP_Y_ctrl" joint="R_HIP_Y" class="motor" />
    <motor name="R_KNEE_P_ctrl" joint="R_KNEE_P" class="motor" />
    <motor name="R_ANKLE_P_ctrl" joint="R_ANKLE_P" class="motor" />
    <motor name="R_ANKLE_R_ctrl" joint="R_ANKLE_R" class="motor" />
    <motor name="WAIST_Y_ctrl" joint="WAIST_Y" class="motor" />
    <motor name="WAIST_R_ctrl" joint="WAIST_R" class="motor" />
    <motor name="WAIST_P_ctrl" joint="WAIST_P" class="motor" />
    <motor name="L_SHOULDER_P_ctrl" joint="L_SHOULDER_P" class="motor" />
    <motor name="L_SHOULDER_R_ctrl" joint="L_SHOULDER_R" class="motor" />
    <motor name="L_SHOULDER_Y_ctrl" joint="L_SHOULDER_Y" class="motor" />
    <motor name="L_ELBOW_Y_ctrl" joint="L_ELBOW_Y" class="motor" />
    <motor name="L_WRIST_P_ctrl" joint="L_WRIST_P" class="motor" />
    <motor name="L_WRIST_Y_ctrl" joint="L_WRIST_Y" class="motor" />
    <motor name="L_WRIST_R_ctrl" joint="L_WRIST_R" class="motor" />
    <motor name="R_SHOULDER_P_ctrl" joint="R_SHOULDER_P" class="motor" />
    <motor name="R_SHOULDER_R_ctrl" joint="R_SHOULDER_R" class="motor" />
    <motor name="R_SHOULDER_Y_ctrl" joint="R_SHOULDER_Y" class="motor" />
    <motor name="R_ELBOW_Y_ctrl" joint="R_ELBOW_Y" class="motor" />
    <motor name="R_WRIST_P_ctrl" joint="R_WRIST_P" class="motor" />
    <motor name="R_WRIST_Y_ctrl" joint="R_WRIST_Y" class="motor" />
    <motor name="R_WRIST_R_ctrl" joint="R_WRIST_R" class="motor" />
    <motor name="NECK_Y_ctrl" joint="NECK_Y" class="motor" />
  </actuator>

  <contact>
    <exclude body1="BASE_S" body2="L_HIP_P_S" />
    <exclude body1="L_HIP_P_S" body2="L_HIP_R_S" />
    <exclude body1="L_HIP_R_S" body2="L_HIP_Y_S" />
    <exclude body1="L_HIP_Y_S" body2="L_KNEE_P_S" />
    <exclude body1="L_KNEE_P_S" body2="L_ANKLE_P_S" />
    <exclude body1="L_ANKLE_P_S" body2="L_ANKLE_R_S" />
    <exclude body1="BASE_S" body2="R_HIP_P_S" />
    <exclude body1="R_HIP_P_S" body2="R_HIP_R_S" />
    <exclude body1="R_HIP_R_S" body2="R_HIP_Y_S" />
    <exclude body1="R_HIP_Y_S" body2="R_KNEE_P_S" />
    <exclude body1="R_KNEE_P_S" body2="R_ANKLE_P_S" />
    <exclude body1="R_ANKLE_P_S" body2="R_ANKLE_R_S" />
    <exclude body1="BASE_S" body2="WAIST_Y_S" />
    <exclude body1="WAIST_Y_S" body2="WAIST_R_S" />
    <exclude body1="WAIST_R_S" body2="WAIST_P_S" />
    <exclude body1="WAIST_P_S" body2="L_SHOULDER_P_S" />
    <exclude body1="L_SHOULDER_P_S" body2="L_SHOULDER_R_S" />
    <exclude body1="L_SHOULDER_R_S" body2="L_SHOULDER_Y_S" />
    <exclude body1="L_SHOULDER_Y_S" body2="L_ELBOW_Y_S" />
    <exclude body1="L_ELBOW_Y_S" body2="L_WRIST_P_S" />
    <exclude body1="L_WRIST_P_S" body2="L_WRIST_Y_S" />
    <exclude body1="L_WRIST_Y_S" body2="L_WRIST_R_S" />
    <exclude body1="WAIST_P_S" body2="R_SHOULDER_P_S" />
    <exclude body1="R_SHOULDER_P_S" body2="R_SHOULDER_R_S" />
    <exclude body1="R_SHOULDER_R_S" body2="R_SHOULDER_Y_S" />
    <exclude body1="R_SHOULDER_Y_S" body2="R_ELBOW_Y_S" />
    <exclude body1="R_ELBOW_Y_S" body2="R_WRIST_P_S" />
    <exclude body1="R_WRIST_P_S" body2="R_WRIST_Y_S" />
    <exclude body1="R_WRIST_Y_S" body2="R_WRIST_R_S" />
    <exclude body1="WAIST_P_S" body2="NECK_Y_S" />
  </contact>

  <sensor>
    <framepos name="world_site_pos" objtype="site" objname="world_site" />
    <framequat name="world_site_quat" objtype="site" objname="world_site" />
    <framelinvel name="world_site_linvel" objtype="site" objname="world_site" />
    <frameangvel name="world_site_angvel" objtype="site" objname="world_site" />
    <velocimeter name="world_site_vel" site="world_site" />
  </sensor>
</mujoco>